<?xml version="1.0" encoding="utf-8"?>
<!-- =================================================================================== -->
<!-- |    This document was autogenerated by xacro from jaskier.xacro                  | -->
<!-- |    EDITING THIS FILE BY HAND IS NOT RECOMMENDED                                 | -->
<!-- =================================================================================== -->
<robot name="jaskier">
  <link name="base_link">
    <visual>
      <geometry>
        <box size="0.08 0.08 0.02"/>
      </geometry>
      <material name="Magenta">
        <color rgba="1.0 0 1.0 1.0"/>
      </material>
    </visual>
  </link>
  <link name="thumb">
    <visual>
      <geometry>
        <cylinder length="0.1" radius="0.0075"/>
      </geometry>
      <origin rpy="-1.57079632679 0.785398163397 0" xyz="-0.04 -0.04 0"/>
      <material name="cyan">
        <color rgba="0 1.0 1.0 1.0"/>
      </material>
    </visual>
    <collision>
      <geometry>
        <sphere radius="0.0075"/>
      </geometry>
      <origin rpy="0 0 0" xyz="0 0.1 0"/>
    </collision>
  </link>
  <link name="index">
    <visual>
      <geometry>
        <cylinder length="0.1" radius="0.0075"/>
      </geometry>
      <origin rpy="0 0 0" xyz="-0.04 0.04 0"/>
      <material name="cyan">
        <color rgba="0 1.0 1.0 1.0"/>
      </material>
    </visual>
    <collision>
      <geometry>
        <sphere radius="0.0075"/>
      </geometry>
      <origin rpy="0 0 0" xyz="0 0.1 0"/>
    </collision>
  </link>
  <link name="middle">
    <visual>
      <geometry>
        <cylinder length="0.1" radius="0.0075"/>
      </geometry>
      <origin rpy="0 0 0" xyz="-0.0133333333333 0.04 0"/>
      <material name="cyan">
        <color rgba="0 1.0 1.0 1.0"/>
      </material>
    </visual>
    <collision>
      <geometry>
        <sphere radius="0.0075"/>
      </geometry>
      <origin rpy="0 0 0" xyz="0 0.1 0"/>
    </collision>
  </link>
  <link name="ring">
    <visual>
      <geometry>
        <cylinder length="0.1" radius="0.0075"/>
      </geometry>
      <origin rpy="0 0 0" xyz="0.0133333333333 0.04 0"/>
      <material name="cyan">
        <color rgba="0 1.0 1.0 1.0"/>
      </material>
    </visual>
    <collision>
      <geometry>
        <sphere radius="0.0075"/>
      </geometry>
      <origin rpy="0 0 0" xyz="0 0.1 0"/>
    </collision>
  </link>
  <link name="little">
    <visual>
      <geometry>
        <cylinder length="0.1" radius="0.0075"/>
      </geometry>
      <origin rpy="0 0 0" xyz="0.04 0.04 0"/>
      <material name="cyan">
        <color rgba="0 1.0 1.0 1.0"/>
      </material>
    </visual>
    <collision>
      <geometry>
        <sphere radius="0.0075"/>
      </geometry>
      <origin rpy="0 0 0" xyz="0 0.1 0"/>
    </collision>
  </link>
  <joint name="thumb_joint" type="revolute">
    <parent link="base_link"/>
    <child link="thumb"/>
    <axis xyz="0 1 0"/>
    <limit effort="0.0" lower="0.0" upper="1.8" velocity="20"/>
    <origin rpy="-1.57079632679 0.785398163397 0" xyz="-0.04 -0.04 0"/>
  </joint>
  <joint name="index_joint" type="revolute">
    <parent link="base_link"/>
    <child link="index"/>
    <axis xyz="0 1 0"/>
    <limit effort="0.0" lower="0.0" upper="1.8" velocity="20"/>
    <origin rpy="0 0 0" xyz="-0.04 0.04 0"/>
  </joint>
  <joint name="middle_joint" type="revolute">
    <parent link="base_link"/>
    <child link="middle"/>
    <axis xyz="0 1 0"/>
    <limit effort="0.0" lower="0.0" upper="1.8" velocity="20"/>
    <origin rpy="0 0 0" xyz="-0.0133333333333 0.04 0"/>
  </joint>
  <joint name="ring_joint" type="revolute">
    <parent link="base_link"/>
    <child link="ring"/>
    <axis xyz="0 1 0"/>
    <limit effort="0.0" lower="0.0" upper="1.8" velocity="20"/>
    <origin rpy="0 0 0" xyz="0.0133333333333 0.04 0"/>
  </joint>
  <joint name="little_joint" type="revolute">
    <parent link="base_link"/>
    <child link="little"/>
    <axis xyz="0 1 0"/>
    <limit effort="0.0" lower="0.0" upper="1.8" velocity="20"/>
    <origin rpy="0 0 0" xyz="0.04 0.04 0"/>
  </joint>
</robot>

