<?xml version="1.0" encoding="utf-8"?>
<!-- =================================================================================== -->
<!-- |    This document was autogenerated by xacro from jaskier.xacro                  | -->
<!-- |    EDITING THIS FILE BY HAND IS NOT RECOMMENDED                                 | -->
<!-- =================================================================================== -->
<robot name="jaskier">
  <link name="hand_link">
    <visual>
      <geometry>
        <box size="0.085 0.061 0.02"/>
      </geometry>
      <material name="Magenta">
        <color rgba="1.0 0 1.0 1.0"/>
      </material>
    </visual>
  </link>
  <link name="thumb_proximal">
    <visual>
      <geometry>
        <cylinder length="0.034" radius="0.0085"/>
      </geometry>
      <origin rpy="0 0 0" xyz="0 0 -0.017"/>
      <material name="cyan">
        <color rgba="0 1.0 1.0 1.0"/>
      </material>
    </visual>
  </link>
  <link name="thumb_distal">
    <visual>
      <geometry>
        <cylinder length="0.032" radius="0.0085"/>
      </geometry>
      <origin rpy="0 0 0" xyz="0 0 -0.016"/>
      <material name="cyan">
        <color rgba="0 1.0 1.0 1.0"/>
      </material>
    </visual>
    <collision>
      <geometry>
        <sphere radius="0.0085"/>
      </geometry>
      <origin rpy="0 0 0" xyz="0 0 -0.032"/>
    </collision>
  </link>
  <link name="index_proximal">
    <visual>
      <geometry>
        <cylinder length="0.026" radius="0.0065"/>
      </geometry>
      <origin rpy="0 0 0" xyz="0 0 -0.013"/>
      <material name="cyan">
        <color rgba="0 1.0 1.0 1.0"/>
      </material>
    </visual>
  </link>
  <link name="index_middle">
    <visual>
      <geometry>
        <cylinder length="0.024" radius="0.0065"/>
      </geometry>
      <origin rpy="0 0 0" xyz="0 0 -0.012"/>
      <material name="cyan">
        <color rgba="0 1.0 1.0 1.0"/>
      </material>
    </visual>
  </link>
  <link name="index_distal">
    <visual>
      <geometry>
        <cylinder length="0.026" radius="0.0065"/>
      </geometry>
      <origin rpy="0 0 0" xyz="0 0 -0.013"/>
      <material name="cyan">
        <color rgba="0 1.0 1.0 1.0"/>
      </material>
    </visual>
    <collision>
      <geometry>
        <sphere radius="0.0065"/>
      </geometry>
      <origin rpy="0 0 0" xyz="0 0 -0.026"/>
    </collision>
  </link>
  <link name="middle_proximal">
    <visual>
      <geometry>
        <cylinder length="0.026" radius="0.007"/>
      </geometry>
      <origin rpy="0 0 0" xyz="0 0 -0.013"/>
      <material name="cyan">
        <color rgba="0 1.0 1.0 1.0"/>
      </material>
    </visual>
  </link>
  <link name="middle_middle">
    <visual>
      <geometry>
        <cylinder length="0.027" radius="0.007"/>
      </geometry>
      <origin rpy="0 0 0" xyz="0 0 -0.0135"/>
      <material name="cyan">
        <color rgba="0 1.0 1.0 1.0"/>
      </material>
    </visual>
  </link>
  <link name="middle_distal">
    <visual>
      <geometry>
        <cylinder length="0.027" radius="0.007"/>
      </geometry>
      <origin rpy="0 0 0" xyz="0 0 -0.0135"/>
      <material name="cyan">
        <color rgba="0 1.0 1.0 1.0"/>
      </material>
    </visual>
    <collision>
      <geometry>
        <sphere radius="0.007"/>
      </geometry>
      <origin rpy="0 0 0" xyz="0 0 -0.027"/>
    </collision>
  </link>
  <link name="ring_proximal">
    <visual>
      <geometry>
        <cylinder length="0.026" radius="0.0065"/>
      </geometry>
      <origin rpy="0 0 0" xyz="0 0 -0.013"/>
      <material name="cyan">
        <color rgba="0 1.0 1.0 1.0"/>
      </material>
    </visual>
  </link>
  <link name="ring_middle">
    <visual>
      <geometry>
        <cylinder length="0.024" radius="0.0065"/>
      </geometry>
      <origin rpy="0 0 0" xyz="0 0 -0.012"/>
      <material name="cyan">
        <color rgba="0 1.0 1.0 1.0"/>
      </material>
    </visual>
  </link>
  <link name="ring_distal">
    <visual>
      <geometry>
        <cylinder length="0.027" radius="0.0065"/>
      </geometry>
      <origin rpy="0 0 0" xyz="0 0 -0.0135"/>
      <material name="cyan">
        <color rgba="0 1.0 1.0 1.0"/>
      </material>
    </visual>
    <collision>
      <geometry>
        <sphere radius="0.0065"/>
      </geometry>
      <origin rpy="0 0 0" xyz="0 0 -0.027"/>
    </collision>
  </link>
  <link name="little_proximal">
    <visual>
      <geometry>
        <cylinder length="0.018" radius="0.006"/>
      </geometry>
      <origin rpy="0 0 0" xyz="0 0 -0.009"/>
      <material name="cyan">
        <color rgba="0 1.0 1.0 1.0"/>
      </material>
    </visual>
  </link>
  <link name="little_middle">
    <visual>
      <geometry>
        <cylinder length="0.017" radius="0.006"/>
      </geometry>
      <origin rpy="0 0 0" xyz="0 0 -0.0085"/>
      <material name="cyan">
        <color rgba="0 1.0 1.0 1.0"/>
      </material>
    </visual>
  </link>
  <link name="little_distal">
    <visual>
      <geometry>
        <cylinder length="0.025" radius="0.006"/>
      </geometry>
      <origin rpy="0 0 0" xyz="0 0 -0.0125"/>
      <material name="cyan">
        <color rgba="0 1.0 1.0 1.0"/>
      </material>
    </visual>
    <collision>
      <geometry>
        <sphere radius="0.006"/>
      </geometry>
      <origin rpy="0 0 0" xyz="0 0 -0.025"/>
    </collision>
  </link>
  <link name="imu_x_link"/>
  <link name="imu_y_link"/>
  <link name="imu_z_link"/>
  <link name="ultra_x_link"/>
  <link name="ultra_y_link"/>
  <link name="ultra_z_link"/>
  <link name="base_link"/>
  <joint name="imu_x" type="continuous">
    <parent link="imu_x_link"/>
    <child link="hand_link"/>
    <axis xyz="1 0 0"/>
  </joint>
  <joint name="imu_y" type="continuous">
    <parent link="imu_y_link"/>
    <child link="imu_x_link"/>
    <axis xyz="0 1 0"/>
  </joint>
  <joint name="imu_z" type="continuous">
    <parent link="imu_z_link"/>
    <child link="imu_y_link"/>
    <axis xyz="0 0 1"/>
  </joint>
  <joint name="ultra_x" type="prismatic">
    <parent link="ultra_x_link"/>
    <child link="imu_z_link"/>
    <axis xyz="1 0 0"/>
    <limit effort="0.0" lower="-20" upper="20" velocity="20"/>
  </joint>
  <joint name="ultra_y" type="prismatic">
    <parent link="ultra_y_link"/>
    <child link="ultra_x_link"/>
    <axis xyz="0 1 0"/>
    <limit effort="0.0" lower="-20" upper="20" velocity="20"/>
  </joint>
  <joint name="ultra_z" type="prismatic">
    <parent link="ultra_z_link"/>
    <child link="ultra_y_link"/>
    <axis xyz="0 0 1"/>
    <limit effort="0.0" lower="-20" upper="20" velocity="20"/>
  </joint>
  <joint name="base_joint" type="fixed">
    <parent link="base_link"/>
    <child link="ultra_z_link"/>
  </joint>
  <joint name="thumb_mcp" type="revolute">
    <parent link="hand_link"/>
    <child link="thumb_proximal"/>
    <axis xyz="0 1 0"/>
    <limit effort="0.0" lower="-1.8" upper="0" velocity="20"/>
    <origin rpy="0.9 0.6 0" xyz="-0.0425 -0.0305 -0.02"/>
  </joint>
  <joint name="thumb_ip" type="revolute">
    <parent link="thumb_proximal"/>
    <child link="thumb_distal"/>
    <axis xyz="0 1 0"/>
    <limit effort="0.0" lower="-1.8" upper="0" velocity="20"/>
    <origin rpy="0 0 0" xyz="0 0 -0.034"/>
  </joint>
  <joint name="index_mcp" type="revolute">
    <parent link="hand_link"/>
    <child link="index_proximal"/>
    <axis xyz="1 0 0"/>
    <limit effort="0.0" lower="-1.8" upper="0" velocity="20"/>
    <origin rpy="1.57079632679 0 0" xyz="-0.0425 0.0305 0"/>
  </joint>
  <joint name="index_pip" type="revolute">
    <parent link="index_proximal"/>
    <child link="index_middle"/>
    <axis xyz="1 0 0"/>
    <limit effort="0.0" lower="-1.8" upper="0" velocity="20"/>
    <origin rpy="0 0 0" xyz="0 0 -0.026"/>
  </joint>
  <joint name="index_dip" type="revolute">
    <parent link="index_middle"/>
    <child link="index_distal"/>
    <axis xyz="1 0 0"/>
    <limit effort="0.0" lower="-1.8" upper="0" velocity="20"/>
    <origin rpy="0 0 0" xyz="0 0 -0.024"/>
  </joint>
  <joint name="middle_mcp" type="revolute">
    <parent link="hand_link"/>
    <child link="middle_proximal"/>
    <axis xyz="1 0 0"/>
    <limit effort="0.0" lower="-1.8" upper="0" velocity="20"/>
    <origin rpy="1.57079632679 0 0" xyz="-0.0141666666667 0.0305 0"/>
  </joint>
  <joint name="middle_pip" type="revolute">
    <parent link="middle_proximal"/>
    <child link="middle_middle"/>
    <axis xyz="1 0 0"/>
    <limit effort="0.0" lower="-1.8" upper="0" velocity="20"/>
    <origin rpy="0 0 0" xyz="0 0 -0.026"/>
  </joint>
  <joint name="middle_dip" type="revolute">
    <parent link="middle_middle"/>
    <child link="middle_distal"/>
    <axis xyz="1 0 0"/>
    <limit effort="0.0" lower="-1.8" upper="0" velocity="20"/>
    <origin rpy="0 0 0" xyz="0 0 -0.027"/>
  </joint>
  <joint name="ring_mcp" type="revolute">
    <parent link="hand_link"/>
    <child link="ring_proximal"/>
    <axis xyz="1 0 0"/>
    <limit effort="0.0" lower="-1.8" upper="0" velocity="20"/>
    <origin rpy="1.57079632679 0 0" xyz="0.0141666666667 0.0305 0"/>
  </joint>
  <joint name="ring_pip" type="revolute">
    <parent link="ring_proximal"/>
    <child link="ring_middle"/>
    <axis xyz="1 0 0"/>
    <limit effort="0.0" lower="-1.8" upper="0" velocity="20"/>
    <origin rpy="0 0 0" xyz="0 0 -0.026"/>
  </joint>
  <joint name="ring_dip" type="revolute">
    <parent link="ring_middle"/>
    <child link="ring_distal"/>
    <axis xyz="1 0 0"/>
    <limit effort="0.0" lower="-1.8" upper="0" velocity="20"/>
    <origin rpy="0 0 0" xyz="0 0 -0.024"/>
  </joint>
  <joint name="little_mcp" type="revolute">
    <parent link="hand_link"/>
    <child link="little_proximal"/>
    <axis xyz="1 0 0"/>
    <limit effort="0.0" lower="-1.8" upper="0" velocity="20"/>
    <origin rpy="1.57079632679 0 0" xyz="0.0425 0.0305 0"/>
  </joint>
  <joint name="little_pip" type="revolute">
    <parent link="little_proximal"/>
    <child link="little_middle"/>
    <axis xyz="1 0 0"/>
    <limit effort="0.0" lower="-1.8" upper="0" velocity="20"/>
    <origin rpy="0 0 0" xyz="0 0 -0.018"/>
  </joint>
  <joint name="little_dip" type="revolute">
    <parent link="little_middle"/>
    <child link="little_distal"/>
    <axis xyz="1 0 0"/>
    <limit effort="0.0" lower="-1.8" upper="0" velocity="20"/>
    <origin rpy="0 0 0" xyz="0 0 -0.017"/>
  </joint>
</robot>

